2025-01-29 09:24:19,660:DEBUG:certbot._internal.main:certbot version: 3.1.0
2025-01-29 09:24:19,661:DEBUG:certbot._internal.main:Location of certbot entry point: /usr/local/bin/certbot
2025-01-29 09:24:19,661:DEBUG:certbot._internal.main:Arguments: ['--webroot', '--webroot-path=/var/www/html', '--email', 'gusarov.as@fltrktv.ru', '--agree-tos', '--no-eff-email', '-d', 'fltrktv.ru', '-d', 'www.fltrktv.ru']
2025-01-29 09:24:19,661:DEBUG:certbot._internal.main:Discovered plugins: PluginsRegistry(PluginEntryPoint#manual,PluginEntryPoint#null,PluginEntryPoint#standalone,PluginEntryPoint#webroot)
2025-01-29 09:24:19,672:DEBUG:certbot._internal.log:Root logging level set at 30
2025-01-29 09:24:19,673:DEBUG:certbot._internal.plugins.selection:Requested authenticator webroot and installer None
2025-01-29 09:24:19,673:DEBUG:certbot._internal.plugins.selection:Single candidate plugin: * webroot
Description: Saves the necessary validation files to a .well-known/acme-challenge/ directory within the nominated webroot path. A separate HTTP server must be running and serving files from the webroot path. HTTP challenge only (wildcards not supported).
Interfaces: Authenticator, Plugin
Entry point: EntryPoint(name='webroot', value='certbot._internal.plugins.webroot:Authenticator', group='certbot.plugins')
Initialized: <certbot._internal.plugins.webroot.Authenticator object at 0x7f002493e720>
Prep: True
2025-01-29 09:24:19,673:DEBUG:certbot._internal.plugins.selection:Selected authenticator <certbot._internal.plugins.webroot.Authenticator object at 0x7f002493e720> and installer None
2025-01-29 09:24:19,673:INFO:certbot._internal.plugins.selection:Plugins selected: Authenticator webroot, Installer None
2025-01-29 09:24:19,713:DEBUG:certbot._internal.main:Picked account: <Account(RegistrationResource(body=Registration(key=None, contact=(), agreement=None, status=None, terms_of_service_agreed=None, only_return_existing=None, external_account_binding=None), uri='https://acme-v02.api.letsencrypt.org/acme/acct/2188860915', new_authzr_uri=None, terms_of_service=None), 07fbde8bedab8a49b720c3ac37096954, Meta(creation_dt=datetime.datetime(2025, 1, 24, 13, 38, 56, tzinfo=datetime.timezone.utc), creation_host='d4dcd3174b6e', register_to_eff=None))>
2025-01-29 09:24:19,714:DEBUG:acme.client:Sending GET request to https://acme-v02.api.letsencrypt.org/directory.
2025-01-29 09:24:19,717:DEBUG:urllib3.connectionpool:Starting new HTTPS connection (1): acme-v02.api.letsencrypt.org:443
2025-01-29 09:24:20,344:DEBUG:urllib3.connectionpool:https://acme-v02.api.letsencrypt.org:443 "GET /directory HTTP/1.1" 200 828
2025-01-29 09:24:20,344:DEBUG:acme.client:Received response:
HTTP 200
Server: nginx
Date: Wed, 29 Jan 2025 09:24:23 GMT
Content-Type: application/json
Content-Length: 828
Connection: keep-alive
Cache-Control: public, max-age=0, no-cache
X-Frame-Options: DENY
Strict-Transport-Security: max-age=604800

{
  "MgvfzOnn5Kw": "https://community.letsencrypt.org/t/adding-random-entries-to-the-directory/33417",
  "keyChange": "https://acme-v02.api.letsencrypt.org/acme/key-change",
  "meta": {
    "caaIdentities": [
      "letsencrypt.org"
    ],
    "profiles": {
      "classic": "The same profile you're accustomed to"
    },
    "termsOfService": "https://letsencrypt.org/documents/LE-SA-v1.4-April-3-2024.pdf",
    "website": "https://letsencrypt.org"
  },
  "newAccount": "https://acme-v02.api.letsencrypt.org/acme/new-acct",
  "newNonce": "https://acme-v02.api.letsencrypt.org/acme/new-nonce",
  "newOrder": "https://acme-v02.api.letsencrypt.org/acme/new-order",
  "renewalInfo": "https://acme-v02.api.letsencrypt.org/draft-ietf-acme-ari-03/renewalInfo",
  "revokeCert": "https://acme-v02.api.letsencrypt.org/acme/revoke-cert"
}
2025-01-29 09:24:20,348:DEBUG:urllib3.connectionpool:Starting new HTTP connection (1): e6.o.lencr.org:80
2025-01-29 09:24:24,832:DEBUG:urllib3.connectionpool:http://e6.o.lencr.org:80 "POST / HTTP/1.1" 200 345
2025-01-29 09:24:24,834:DEBUG:certbot.ocsp:OCSP response for certificate /etc/letsencrypt/archive/fltrktv.ru/cert1.pem is signed by the certificate's issuer.
2025-01-29 09:24:24,838:DEBUG:certbot.ocsp:OCSP certificate status for /etc/letsencrypt/archive/fltrktv.ru/cert1.pem is: OCSPCertStatus.GOOD
2025-01-29 09:24:24,846:DEBUG:certbot._internal.display.obj:Notifying user: Certificate not yet due for renewal
2025-01-29 09:24:24,847:DEBUG:certbot._internal.log:Exiting abnormally:
Traceback (most recent call last):
  File "/usr/local/bin/certbot", line 33, in <module>
    sys.exit(load_entry_point('certbot', 'console_scripts', 'certbot')())
             ^^^^^^^^^^^^^^^^^^^^^^^^^^^^^^^^^^^^^^^^^^^^^^^^^^^^^^^^^^^
  File "/opt/certbot/src/certbot/certbot/main.py", line 19, in main
    return internal_main.main(cli_args)
           ^^^^^^^^^^^^^^^^^^^^^^^^^^^^
  File "/opt/certbot/src/certbot/certbot/_internal/main.py", line 1873, in main
    return config.func(config, plugins)
           ^^^^^^^^^^^^^^^^^^^^^^^^^^^^
  File "/opt/certbot/src/certbot/certbot/_internal/main.py", line 1572, in certonly
    should_get_cert, lineage = _find_cert(config, domains, certname)
                               ^^^^^^^^^^^^^^^^^^^^^^^^^^^^^^^^^^^^^
  File "/opt/certbot/src/certbot/certbot/_internal/main.py", line 363, in _find_cert
    action, lineage = _find_lineage_for_domains_and_certname(config, domains, certname)
                      ^^^^^^^^^^^^^^^^^^^^^^^^^^^^^^^^^^^^^^^^^^^^^^^^^^^^^^^^^^^^^^^^^
  File "/opt/certbot/src/certbot/certbot/_internal/main.py", line 393, in _find_lineage_for_domains_and_certname
    return _find_lineage_for_domains(config, domains)
           ^^^^^^^^^^^^^^^^^^^^^^^^^^^^^^^^^^^^^^^^^^
  File "/opt/certbot/src/certbot/certbot/_internal/main.py", line 338, in _find_lineage_for_domains
    return _handle_identical_cert_request(config, ident_names_cert)
           ^^^^^^^^^^^^^^^^^^^^^^^^^^^^^^^^^^^^^^^^^^^^^^^^^^^^^^^^
  File "/opt/certbot/src/certbot/certbot/_internal/main.py", line 289, in _handle_identical_cert_request
    response = display_util.menu(question, choices,
               ^^^^^^^^^^^^^^^^^^^^^^^^^^^^^^^^^^^^
  File "/opt/certbot/src/certbot/certbot/display/util.py", line 80, in menu
    return obj.get_display().menu(message, choices, default=default, cli_flag=cli_flag,
           ^^^^^^^^^^^^^^^^^^^^^^^^^^^^^^^^^^^^^^^^^^^^^^^^^^^^^^^^^^^^^^^^^^^^^^^^^^^^
  File "/opt/certbot/src/certbot/certbot/_internal/display/obj.py", line 125, in menu
    code, selection = self._get_valid_int_ans(len(choices))
                      ^^^^^^^^^^^^^^^^^^^^^^^^^^^^^^^^^^^^^
  File "/opt/certbot/src/certbot/certbot/_internal/display/obj.py", line 391, in _get_valid_int_ans
    ans = util.input_with_timeout(input_msg)
          ^^^^^^^^^^^^^^^^^^^^^^^^^^^^^^^^^^
  File "/opt/certbot/src/certbot/certbot/_internal/display/util.py", line 68, in input_with_timeout
    raise EOFError
EOFError
2025-01-29 09:24:24,853:ERROR:certbot._internal.log:An unexpected error occurred:
2025-01-29 09:24:24,853:ERROR:certbot._internal.log:EOFError
